<sdf version='1.7'>
  <model name='hexa_x_tilt'>
    <link name='base_link'>
      <inertial>
        <pose>0 0 0 0 -0 0</pose>
        <mass>5</mass>
        <inertia>
          <ixx>0.3</ixx>
          <ixy>0</ixy>
          <ixz>0</ixz>
          <iyy>0.3</iyy>
          <iyz>0</iyz>
          <izz>0.3</izz>
        </inertia>
      </inertial>
      <collision name='base_link_collision_collision'>
        <pose>0 0 0 1.57 0 3.14</pose>
        <geometry>
          <mesh>
            <scale>0.001 0.001 0.001</scale>
            <uri>model://hexa_x_tilt/meshes/main_body.stl</uri>
          </mesh>
        </geometry>
      </collision>
      <visual name='base_link_visual_visual'>
        <pose>0 0 0 1.57 0 3.14</pose>
        <geometry>
          <mesh>
            <scale>0.001 0.001 0.001</scale>
            <uri>model://hexa_x_tilt/meshes/main_body.stl</uri>
          </mesh>
        </geometry>
      </visual>
    </link>
    <joint name='manipulator_base_yaw_joint' type='revolute'>
      <pose relative_to='base_link'>0.06 0 0.065 0 -0 0</pose>
      <parent>base_link</parent>
      <child>manipulator_base_yaw</child>
      <axis>
        <xyz>0 0 1</xyz>
        <limit>
          <lower>-3.1</lower>
          <upper>3.1</upper>
          <effort>10</effort>
          <velocity>1</velocity>
        </limit>
        <dynamics>
          <spring_reference>0</spring_reference>
          <spring_stiffness>0</spring_stiffness>
        </dynamics>
      </axis>
    </joint>
    <link name='manipulator_base_yaw'>
      <pose relative_to='manipulator_base_yaw_joint'>0 0 0 0 -0 0</pose>
      <inertial>
        <pose>0 0 0 0 -0 0</pose>
        <mass>0.3</mass>
        <inertia>
          <ixx>0.0005</ixx>
          <ixy>0</ixy>
          <ixz>0</ixz>
          <iyy>0.0005</iyy>
          <iyz>0</iyz>
          <izz>0.0005</izz>
        </inertia>
      </inertial>
      <collision name='manipulator_base_yaw_collision_collision'>
        <pose>0 0 0 1.57 -0 0</pose>
        <geometry>
          <mesh>
            <scale>0.001 0.001 0.001</scale>
            <uri>model://hexa_x_tilt/meshes/arm_base_yaw.stl</uri>
          </mesh>
        </geometry>
      </collision>
      <visual name='manipulator_base_yaw_visual_visual'>
        <pose>0 0 0 1.57 -0 0</pose>
        <geometry>
          <mesh>
            <scale>0.001 0.001 0.001</scale>
            <uri>model://hexa_x_tilt/meshes/arm_base_yaw.stl</uri>
          </mesh>
        </geometry>
      </visual>
    </link>
    <joint name='manipulator_arm1_joint' type='revolute'>
      <pose relative_to='manipulator_base_yaw'>0 0 0.0485 0 -0 0</pose>
      <parent>manipulator_base_yaw</parent>
      <child>manipulator_arm1</child>
      <axis>
        <xyz>0 1 0</xyz>
        <limit>
          <lower>-3.1</lower>
          <upper>3.1</upper>
          <effort>10</effort>
          <velocity>1</velocity>
        </limit>
        <dynamics>
          <spring_reference>0</spring_reference>
          <spring_stiffness>0</spring_stiffness>
        </dynamics>
      </axis>
    </joint>
    <link name='manipulator_arm1'>
      <pose relative_to='manipulator_arm1_joint'>0 0 0 0 -0 0</pose>
      <inertial>
        <pose>0 0 0 0 -0 0</pose>
        <mass>0.3</mass>
        <inertia>
          <ixx>0.007</ixx>
          <ixy>0</ixy>
          <ixz>0</ixz>
          <iyy>0.007</iyy>
          <iyz>0</iyz>
          <izz>0.0005</izz>
        </inertia>
      </inertial>
      <collision name='manipulator_arm1_collision_collision'>
        <pose>0 0 0 1.5708 -1.5708 0</pose>
        <geometry>
          <mesh>
            <scale>0.001 0.001 0.001</scale>
            <uri>model://hexa_x_tilt/meshes/arm_link1_pitch.stl</uri>
          </mesh>
        </geometry>
      </collision>
      <visual name='manipulator_arm1_visual_visual'>
        <pose>0 0 0 1.5708 -1.5708 0</pose>
        <geometry>
          <mesh>
            <scale>0.001 0.001 0.001</scale>
            <uri>model://hexa_x_tilt/meshes/arm_link1_pitch.stl</uri>
          </mesh>
        </geometry>
      </visual>
    </link>
    <joint name='manipulator_arm2_joint' type='revolute'>
      <pose relative_to='manipulator_arm1'>0 0 0.4435 0 -0 0</pose>
      <parent>manipulator_arm1</parent>
      <child>manipulator_arm2</child>
      <axis>
        <xyz>0 1 0</xyz>
        <limit>
          <lower>-3.1</lower>
          <upper>3.1</upper>
          <effort>10</effort>
          <velocity>1</velocity>
        </limit>
        <dynamics>
          <spring_reference>0</spring_reference>
          <spring_stiffness>0</spring_stiffness>
        </dynamics>
      </axis>
    </joint>
    <link name='manipulator_arm2'>
      <pose relative_to='manipulator_arm2_joint'>0 0 0 0 -0 0</pose>
      <inertial>
        <pose>0 0 0.1115 0 -0 0</pose>
        <mass>0.4</mass>
        <inertia>
          <ixx>0.0221187</ixx>
          <ixy>0</ixy>
          <ixz>0</ixz>
          <iyy>0.0221187</iyy>
          <iyz>0</iyz>
          <izz>0.0007</izz>
        </inertia>
      </inertial>
      <collision name='manipulator_arm2_collision_collision'>
        <pose>0 0 0 1.5708 -1.5708 0</pose>
        <geometry>
          <mesh>
            <scale>0.001 0.001 0.001</scale>
            <uri>model://hexa_x_tilt/meshes/arm_link2_pitch.stl</uri>
          </mesh>
        </geometry>
      </collision>
      <collision name='manipulator_arm2_fixed_joint_lump__manipulator_finger1_collision_collision_1'>
        <pose>0 0 0.446 1.57 0 -1.57</pose>
        <geometry>
          <mesh>
            <scale>0.001 0.001 0.001</scale>
            <uri>model://hexa_x_tilt/meshes/finger.stl</uri>
          </mesh>
        </geometry>
      </collision>
      <collision name='manipulator_arm2_fixed_joint_lump__manipulator_finger2_collision_collision_2'>
        <pose>0 0 0.446 1.57 -0 1.57</pose>
        <geometry>
          <mesh>
            <scale>0.001 0.001 0.001</scale>
            <uri>model://hexa_x_tilt/meshes/finger.stl</uri>
          </mesh>
        </geometry>
      </collision>
      <visual name='manipulator_arm2_visual_visual'>
        <pose>0 0 0 1.5708 -1.5708 0</pose>
        <geometry>
          <mesh>
            <scale>0.001 0.001 0.001</scale>
            <uri>model://hexa_x_tilt/meshes/arm_link2_pitch.stl</uri>
          </mesh>
        </geometry>
      </visual>
      <visual name='manipulator_arm2_fixed_joint_lump__manipulator_finger1_visual_visual_1'>
        <pose>0 0 0.446 1.57 0 -1.57</pose>
        <geometry>
          <mesh>
            <scale>0.001 0.001 0.001</scale>
            <uri>model://hexa_x_tilt/meshes/finger.stl</uri>
          </mesh>
        </geometry>
      </visual>
      <visual name='manipulator_arm2_fixed_joint_lump__manipulator_finger2_visual_visual_2'>
        <pose>0 0 0.446 1.57 -0 1.57</pose>
        <geometry>
          <mesh>
            <scale>0.001 0.001 0.001</scale>
            <uri>model://hexa_x_tilt/meshes/finger.stl</uri>
          </mesh>
        </geometry>
      </visual>
    </link>
    <plugin name='gazebo_ros_control' filename='libgazebo_ros_control.so'>
      <robotNamespace>/hexa_x_tilt</robotNamespace>
      <robotSimType>gazebo_ros_control/DefaultRobotHWSim</robotSimType>
    </plugin>
    <frame name='manipulator_finger1_joint' attached_to='manipulator_arm2'>
      <pose>0 0 0.446 0 -0 0</pose>
    </frame>
    <frame name='manipulator_finger1' attached_to='manipulator_finger1_joint'/>
    <frame name='manipulator_finger2_joint' attached_to='manipulator_arm2'>
      <pose>0 0 0.446 0 -0 0</pose>
    </frame>
    <frame name='manipulator_finger2' attached_to='manipulator_finger2_joint'/>
  </model>
</sdf>
